Workbook
Name Accesories_citel: OFFSET(Items!#REF!,,,COUNTA(#REF!))
Name BATTERY_TYPE: OFFSET(Items!#REF!,,,COUNTA(#REF!))
Name BYD_Lithium: Items!$AN$205:$AN$212
Name BYD_Solar_Panel: Items!$AN$242:$AN$243
Name CLIENT_info: OFFSET('Customer Base'!#REF!,,,COUNTA('Customer Base'!#REF!))
Name CurrentUser: #REF!
Name Deye: Items!$AN$77:$AN$83
Name EasySolar: Items!$AN$62
Name EasySolar_II: Items!$AN$64:$AN$66
Name Eco: Items!$AN$117:$AN$118
Name Freedom_Won: Items!#REF!
Name Galvo: Items!$AN$103:$AN$105
Name Gen_24_Primo: Items!$AN$122:$AN$124
Name Gen_24_Symo: Items!$AN$125:$AN$132
Name GX_MONITORING: OFFSET(Items!#REF!,,,COUNTA(#REF!))
Name Hoppecke_Lead_Acid: Items!$AN$234:$AN$236
Name Hoppecke_OPzS: Items!#REF!
Name Hoppecke_OPzV: Items!$AN$233:$AN$233
Name Huawei: Items!$AN$86:$AN$94
Name Huawei_Lithium: Items!$AN$217:$AN$219
Name JA_Solar_Panel: Items!#REF!
Name Jinko_Lithium: Items!$AN$215
Name Jinko_Solar_Panel: Items!$AN$245
Name LIST_OF_INVERTER_INVERTER: OFFSET(Items!$C$5,,,COUNTA(Items!$C:$C))
Name MPPT: OFFSET(#REF!,,,COUNTA(#REF!))
Name Multiplus: Items!$AN$26:$AN$45
Name Multiplus_II: Items!$AN$47:$AN$53
Name Multiplus_II_GX: Items!$AN$54:$AN$55
Name Phocos_B: Items!$AN$72
Name Phocos_H: Items!$AN$69:$AN$71
Name Phoenix: Items!$AN$6:$AN$24
Name Primo: Items!$AN$106:$AN$108
Name Quantity: OFFSET(#REF!,,,COUNTA(#REF!))
Name Quattro: Items!$AN$57:$AN$60
Name Select_Location: OFFSET('Customer Base'!#REF!,,,COUNTA('Customer Base'!#REF!))
Name Select_Solar_Panel_Type: OFFSET(Items!#REF!,,,COUNTA(#REF!))
Name Sharp_Solar_Panel: Items!$AN$249:$AN$249
Name SheetNames: OFFSET(#REF!,,,COUNTA(#REF!))
Name SHUNTS__FUSES_AND_FUSE_HOLDERS: OFFSET(Items!#REF!,,,COUNTA(#REF!))
Name Symo: Items!$AN$109:$AN$116
Name Tauro: Items!$AN$119:$AN$120
Name TOP_DC_AND_AC_SOLAR_CABLE: OFFSET(Items!$M$4,,,COUNTA(#REF!))
Name Victron_AGM: Items!$AN$221:$AN$231
Name VICTRON_CABLES: OFFSET(Items!#REF!,,,COUNTA(#REF!))
Name Victron_Gel: Items!$AN$232:$AN$232
Name Victron_Lead_Carbon: Items!#REF!
Name VICTRON_SMART_MPPT_SOLAR_CHARGE_CONTROLLERS: OFFSET(#REF!,,,COUNTA(#REF!))
Name Victron_Solar_Panel: Items!$AN$251:$AN$254

Sheet Items
J1: Retail | K1: Number of Strings (Total): | L1: =IF(NOW()>INVOICE!Q13,"",IF(AND('Customer Base'!D7<>"Grid-Tied",'Customer Base'!D7<>"Backup",SUM('Client List'!EE477:EE491)<>0),('Client List'!EE474*'Client List'!EC474),0)+IF(AND('Customer Base'!D7<>"Grid-Tied",'Customer Base'!D7<>"Backup",SUM('Client List'!EE477:EE491)<>0),('Client List'!IM474*'Client List'!IK474),0)+IF(AND('Customer Base'!D7<>"Grid-Tied",'Customer Base'!D7<>"Backup",AND(SUM('Client List'!EE477:EE491)=0,'Client List'!EC474>0)),1,0)+IFERROR(L5,0)) -> 2 | M1: Number of Panels per String: | N1: =IFERROR('Client List'!AC493,IF(AND('Customer Base'!D7<>"Backup",SUMPRODUCT(A6:A132,AP6:AP132)>0),SUM(A242:A254)/L5,0)) -> 4 | AX1: Inverter Capacity | AY1: Multiplus | AZ1: 48/3000/35-50 | BA1: 1 | BB1: =INDEX(AM6:AM284,MATCH(AZ1,AN6:AN284,0)) -> 3 | BC1: kVA | BD1: =INDEX(AQ6:AQ284,MATCH(AZ1,AN6:AN284,0)) -> 48 | BE1: V System
A2: {=INDEX(A6:A549,SMALL(IF(A6:A549<>"",ROW(A6:A549)-MIN(ROW(A6:A549))+1),2))} -> 2 | B2: 2 | J2: Super Dealer | K2: Currency | L2: 600 | M2: Hotel Price + Feeding Per night | P2: ="Exchange Rate: USD 1 = GH₵ "&'Customer Base'!J5 -> Exchange Rate: USD 1 = GH₵ 16.7 | BB2: =INDEX(AM6:AM284,MATCH(AZ4,AN6:AN284,0)) -> 0.555 | BC2: kW | BD2: =INDEX(AQ6:AQ284,MATCH(AZ4,AN6:AN284,0)) -> 49.72 | BE2: Voc
C3: Select items | D3: Retail with Tax | E3: Super Dealer with Tax | F3: End User (USD) | G3: End User (GHC) | H3: SuperDealer (USD) | I3: SuperDealer (GHC) | K3: GH₵ | L3: 35 | M3: GH₵/l | AT3: =IF(SUM(AT6:AT13539)>0,SUBTOTAL(109,(AT6:AT939)),"") -> 2 | AU3: =IF(SUM(AU6:AU13539)>0,SUBTOTAL(109,(AU6:AU939)),"") -> 1 | AV3: =IF(SUM(AV6:AV13539)>0,SUBTOTAL(109,(AV6:AV939)),"") -> 3 | AX3: Battery | AY3: Jinko_Lithium | AZ3: 4.8kWh | BA3: 1 | BB3: =INDEX(AM6:AM284,MATCH(AZ3,AN6:AN284,0)) -> 4.8 | BC3: kWh | BD3: =IF(AND(BD1=12,BC4<0.22,(BD2*ROUNDUP(BC4/BB2,0))<75),75,IF(AND(BD1=12,BC4<0.22,(BD2*ROUNDUP(BC4/BB2,0))/2<75),75,IF(AND(BD1=24,BC4<0.44,(BD2*ROUNDUP(BC4/BB2,0))<75),75,IF(AND(BD1=24,BC4<0.44,(BD2*ROUNDUP(BC4/BB2,0))/2<75),75,IF(AND(BD1=12,BC4<0.7,(BD2*ROUNDUP(BC4/BB2,0))<100),100,IF(AND(BD1=12,BC4<0.7,(BD2*ROUNDUP(BC4/BB2,0))/2<100),100,IF(AND(BD1=24,BC4<1.4,(BD2*ROUNDUP(BC4/BB2,0))<100),100,IF(AND(BD1=24,BC4<1.4,(BD2*ROUNDUP(BC4/BB2,0))/2<100),100,IF(AND(BD1=48,BC4<1.16,(BD2*ROUNDUP(BC4/BB2,0))<100),100,IF(AND(BD1=48,BC4<1.16,(BD2*ROUNDUP(BC4/BB2,0))/2<100),100,IF(AND(BD1=12,BC4<1.45,(BD2*ROUNDUP(BC4/BB2,0))<150),150,IF(AND(BD1=12,BC4<1.45,(BD2*ROUNDUP(BC4/BB2,0))/2<150),150,IF(AND(BD1=24,BC4<4.35,(BD2*ROUNDUP(BC4/BB2,0))<150),150,IF(AND(BD1=24,BC4<4.35,(BD2*ROUNDUP(BC4/BB2,0))/2<150),150,IF(AND(BD1=48,BC4<5.8,(BD2*ROUNDUP(BC4/BB2,0))<150),150,IF(AND(BD1=48,BC4<5.8,(BD2*ROUNDUP(BC4/BB2,0))/2<150),150)))))))))))))))) -> 150 | BE3: V Mppt | BF3: =IF(AND(BD1=12,BB4<0.22),75,IF(AND(BD1=24,BB4<0.44),75,IF(AND(BD1=12,BB4<0.7),100,IF(AND(BD1=24,BB4<1.4),100,IF(AND(BD1=48,BB4<1.16),100,IF(AND(BD1=12,BB4<1.45),150,IF(AND(BD1=24,BB4<4.35),150,IF(AND(BD1=48,BB4<5.8),150,IF(BB4>=5.8,IF(ROUNDUP(MOD(BB4,5.8)/BB2,0)>0,150)))))))))) -> 100 | BG3: =IF(BG4=0,"",IF(AND(BD1=12,BG4<0.22),75,IF(AND(BD1=24,BG4<0.44),75,IF(AND(BD1=12,BG4<0.7),100,IF(AND(BD1=24,BG4<1.4),100,IF(AND(BD1=48,BG4<1.16),100,IF(AND(BD1=12,BG4<1.45),150,IF(AND(BD1=24,BG4<4.35),150,IF(AND(BD1=48,BG4<5.8),150))))))))) | BI3: =ROUNDDOWN(BI4/(ROUNDDOWN(BF3/BD2,0)),0) -> 3 | BJ3: =(ROUNDDOWN(BF3/BD2,0)) -> 2
K4: USD | L4: 10 | M4: km/l | AX4: Solar Panels | AY4: JA_Solar_Panel | AZ4: 555W Mono | BA4: =IF(AND(ROUNDUP(BC4/BB2,0)*BD2>BD3,AND(MOD(ROUNDUP(BC4/BB2,0),3)<>0,MOD(ROUNDUP(BC4/BB2,0),2)<>0)),EVEN(ROUNDUP(BC4/BB2,0)),ROUNDUP(BC4/BB2,0)) -> 6 | BB4: =SUMPRODUCT(AV242:AV254,AM242:AM254)*0.8 -> 0 | BC4: =(BA1*(0.5*BB1/0.8))+(BA3*(BB3/0.8/5)) -> 3.075 | BD4: =ROUNDUP(BC4/BB2,0) -> 6 | BG4: =(BA4-BJ4)*BB2 -> 0 | BH4: =ROUNDUP(MOD(BB4,5.8)/BB2,0) -> 0 | BI4: =BA4-BH4 -> 6 | BJ4: =ROUNDDOWN(BI4/(ROUNDDOWN(BF3/BD2,0)),0)*(ROUNDDOWN(BF3/BD2,0)) -> 6 | BK4: =BA4-BJ4 -> 0 | BL4: ='Customer Base'!$J$9*1000*0.8/$BO$4 -> 3.5068966 | BM4: =MOD('Customer Base'!$J$9*1000*0.8,$BO4) -> 588 | BN4: 20 | BO4: 1160
C5: Victron Inverters | K5: Number of Strings (Non-Victron MPPT): | L5: =IF('Customer Base'!D7<>"Mini-Grid",ROUNDUP(SUM(A242:A254)*(SUMPRODUCT(A242:A254,AQ242:AQ254)/SUM(A242:A254))/(SUMPRODUCT(A6:A132,AP6:AP132)/'Customer Base'!D15),0),IF('Customer Base'!D7="Mini-Grid",ROUNDUP(ROUNDDOWN(PRODUCT('Customer Base'!F14:F15,1000/0.8)/'Customer Base'!D26,0)*(SUMPRODUCT(A242:A254,AQ242:AQ254)/SUM(A242:A254))/(SUMPRODUCT(A6:A132,AP6:AP132)/'Customer Base'!F15),0),0)) -> #DIV/0! | N5: Quantity | O5: =IF('Customer Base'!$I$15="MANUAL",IF(B5<>"",C5,""),IF('Customer Base'!$I$15="AUTOMATE",IF(A5<>"",C5,""),"")) | P5: Description | Q5: Delivery | R5: Payment | S5: Validity | T5: Warranty | U5: System Design | AR5: type | AS5: Phase | AT5: Auto | AU5: Manual | AZ5: Inverter List | BA5: Inverter Capacity | BB5: System Voltage | BC5: Battery List | BD5: Battery Capacity | BE5: Solar Panel List | BL5: ='Customer Base'!$J$9*1000*0.8/$BO$5 -> 2.034 | BM5: =MOD('Customer Base'!$J$9*1000*0.8,$BO5) -> 68 | BN5: 35 | BO5: 2000
A6: =IF(AND('Customer Base'!D$8=12,'Customer Base'!D$13="Victron",'Customer Base'!E$13="Phoenix",'Customer Base'!D$14>0,'Customer Base'!D$14<=0.25),'Customer Base'!D$15,IF(AND('Customer Base'!D$7="Mini-Grid",'Customer Base'!D$8=12,'Customer Base'!F$13="Victron",'Customer Base'!F$14>0,'Customer Base'!F$14<=0.25),'Customer Base'!F$15,"")) | C6: Victron Phoenix Inverter 12/250 230V VE.Direct UK | D6: 97.52 | E6: 91.854 | F6: =$D6/1.219 -> 80 | G6: =IFERROR(ROUNDUP(F6*'Customer Base'!$J$5,2),0) -> 1336 | H6: =$E6/1.219 -> 75.351928 | I6: =IFERROR(ROUNDUP(H6*'Customer Base'!$J$5,2),0) -> 1258.38 | J6: =ROUNDUP((M6/$L$4)*$L$3*3,-1) -> 320 | K6: Greater Accra Region | L6: =J6/'Customer Base'!$J$5 -> 19.161677 | M6: 30 | N6: 1 | O6: =IF('Customer Base'!$I$15="MANUAL",IF(B6<>"",C6,""),IF('Customer Base'!$I$15="AUTOMATE",IF(A6<>"",C6,""),"")) | P6: ="TURNKEY SUPPLY AND INSTALLATION OF "&INVOICE!#REF!&"KWP GRID-CONNECTED SOLAR SYSTEM" -> #REF! | Q6: Delivery: Immediate upon confirmation of payment | R6: Payment: 100% Payment with order | S6: Validity: 1 week from date of invoice | T6: Warranty: 10 years for battery, 5 years for inverter and accessories, 10 years for solar panels | U6: System Design: Hybrid Solar system to supply power to residential facility | W6: DISPLAY TAX | AD6: TINO SOLUTIONS BANKS ACCOUNT DETAILS | AM6: 0.25 | AN6: 12/250 | AO6: =IF('Customer Base'!$I$15="MANUAL",IFERROR(AM6*B6,""),IF('Customer Base'!$I$15="AUTOMATE",IFERROR(AM6*A6,""),"")) | AQ6: 12 | AR6: Phoenix | AS6: 1 | AT6: =IF(AND(AR6=$AY$1,$AZ$1=AN6),BA$1,"") | AV6: =IF(AU6<>"",AU6,AT6) | AX6: =IF(SUMPRODUCT(AS6:AS195,AV6:AV195)>=3,3,1) -> 1 | AZ6: {=INDEX(AR$6:AR$132,MATCH(0,COUNTIF($AZ$5:AZ5,AR$6:AR$132),0))} -> Phoenix | BA6: {=INDEX(AM$6:AM$161,MATCH(0,COUNTIF($BA$5:BA5,AM$6:AM$161),0))} -> 0.25 | BB6: {=INDEX(AQ$6:AQ$161,MATCH(0,COUNTIF($BB$5:BB5,AQ$6:AQ$161),0))} -> 12 | BC6: {=INDEX(AR$205:AR$236,MATCH(0,COUNTIF($BC$5:BC5,AR$205:AR$236),0))} -> BYD_Lithium | BE6: {=INDEX(AR$242:AR$254,MATCH(0,COUNTIF($BE$5:BE5,AR$242:AR$254),0))} -> BYD_Solar_Panel | BL6: ='Customer Base'!$J$9*1000*0.8/$BO$6 -> 1.5646154 | BM6: =MOD('Customer Base'!$J$9*1000*0.8,$BO6) -> 1468 | BN6: 45 | BO6: 2600
A7: =IF(AND('Customer Base'!D$8=12,'Customer Base'!D$13="Victron",'Customer Base'!E$13="Phoenix",'Customer Base'!D$14>0.25,'Customer Base'!D$14<=0.375),'Customer Base'!D$15,IF(AND('Customer Base'!D$7="Mini-Grid",'Customer Base'!D$8=12,'Customer Base'!F$13="Victron",'Customer Base'!F$14>0.25,'Customer Base'!F$14<=0.375),'Customer Base'!F$15,"")) | C7: Victron Phoenix Inverter 12/375 230V VE.Direct UK | D7: 126.42 | E7: 119.07 | F7: =$D7/1.219 -> 103.70796 | G7: =IFERROR(ROUNDUP(F7*'Customer Base'!$J$5,2),0) -> 1731.93 | H7: =$E7/1.219 -> 97.678425 | I7: =IFERROR(ROUNDUP(H7*'Customer Base'!$J$5,2),0) -> 1631.23 | J7: =ROUNDUP((M7/$L$4)*$L$3*3,-1) -> 320 | K7: Accra | L7: =J7/'Customer Base'!$J$5 -> 19.161677 | M7: 30 | N7: 2 | O7: =IF('Customer Base'!$I$15="MANUAL",IF(B7<>"",C7,""),IF('Customer Base'!$I$15="AUTOMATE",IF(A7<>"",C7,""),"")) | P7: SOLAR SYSTEM COMPONENTS COST | Q7: Delivery: Within 30 days after receipt of Purchase Order | R7: Payment: 70% Payment with order, 30% Payment upon system Commissioning | S7: Validity: 2 weeks from date of invoice | T7: Warranty: 1 year for battery, 5 years for inverter and accessories, 10 years for solar panels | U7: System Design: Hybrid Solar system to supply power to commercial facility | W7: DO NOT DISPLAY TAX | AD7: BANK NAME | AE7: CEDIS | AF7: DOLLAR | AG7: ACCOUNT NAME | AJ7: BRANCH | AM7: 0.375 | AN7: 12/375 | AO7: =IF('Customer Base'!$I$15="MANUAL",IFERROR(AM7*B7,""),IF('Customer Base'!$I$15="AUTOMATE",IFERROR(AM7*A7,""),"")) | AQ7: 12 | AR7: Phoenix | AS7: 1 | AT7: =IF(AND(AR7=$AY$1,$AZ$1=AN7),BA$1,"") | AU7: 1 | AV7: =IF(AU7<>"",AU7,AT7) -> 1 | AZ7: {=INDEX(AR$6:AR$132,MATCH(0,COUNTIF($AZ$5:AZ6,AR$6:AR$132),0))} -> 0 | BA7: {=INDEX(AM$6:AM$161,MATCH(0,COUNTIF($BA$5:BA6,AM$6:AM$161),0))} -> 0.375 | BB7: {=INDEX(AQ$6:AQ$161,MATCH(0,COUNTIF($BB$5:BB6,AQ$6:AQ$161),0))} -> 24 | BC7: {=INDEX(AR$205:AR$236,MATCH(0,COUNTIF($BC$5:BC6,AR$205:AR$236),0))} -> 0 | BD7: {=INDEX(AM$205:AM$236,MATCH(0,COUNTIF($BD$5:BD5,AM$205:AM$236),0))} -> 4 | BE7: {=INDEX(AR$242:AR$254,MATCH(0,COUNTIF($BE$5:BE6,AR$242:AR$254),0))} -> 0 | BL7: ='Customer Base'!$J$9*1000*0.8/$BO$7 -> 1.1825581 | BM7: =MOD('Customer Base'!$J$9*1000*0.8,$BO7) -> 628 | BN7: 60 | BO7: 3440
A8: =IF(AND('Customer Base'!D$8=12,'Customer Base'!D$13="Victron",'Customer Base'!E$13="Phoenix",'Customer Base'!D$14>0.375,'Customer Base'!D$14<=0.5),'Customer Base'!D$15,IF(AND('Customer Base'!D$7="Mini-Grid",'Customer Base'!D$8=12,'Customer Base'!F$13="Victron",'Customer Base'!F$14>0.375,'Customer Base'!F$14<=0.5),'Customer Base'!F$15,"")) | C8: Victron Phoenix Inverter 12/500 230V VE.Direct UK | D8: 158.03 | E8: 148.846 | F8: =$D8/1.219 -> 129.63905 | G8: =IFERROR(ROUNDUP(F8*'Customer Base'!$J$5,2),0) -> 2164.98 | H8: =$E8/1.219 -> 122.105 | I8: =IFERROR(ROUNDUP(H8*'Customer Base'!$J$5,2),0) -> 2039.16 | J8: =ROUNDUP((M8/$L$4)*$L$3*3,-1) -> 320 | K8: Tema | L8: =J8/'Customer Base'!$J$5 -> 19.161677 | M8: 30 | N8: 3 | O8: =IF('Customer Base'!$I$15="MANUAL",IF(B8<>"",C8,""),IF('Customer Base'!$I$15="AUTOMATE",IF(A8<>"",C8,""),"")) | P8: DATA LOGGER RENTAL | Q8: Delivery: Within 90 days after receipt of Purchase Order | S8: Validity: 30 days from date of invoice | T8: Warranty: 5 years for inverter and accessories, 10 years for solar panels | U8: System Design: Grid-tied solar system for commercial facility | AD8: Bank Name: ACCESS BANK (GHANA) PLC | AE8: Account No: 0200223082501 (GHS) | AF8: Account No: 0201013082501 (USD) | AG8: Account Name: Tino Solutions Limited | AH8: Swift Code: ABNGGHACXXX | AI8: Sort Code: 280114 | AJ8: Bank Branch: Abeka Lapaz | AM8: 0.5 | AN8: 12/500 | AO8: =IF('Customer Base'!$I$15="MANUAL",IFERROR(AM8*B8,""),IF('Customer Base'!$I$15="AUTOMATE",IFERROR(AM8*A8,""),"")) | AQ8: 12 | AR8: Phoenix | AS8: 1 | AT8: =IF(AND(AR8=$AY$1,$AZ$1=AN8),BA$1,"") | AV8: =IF(AU8<>"",AU8,AT8) | AZ8: {=INDEX(AR$6:AR$132,MATCH(0,COUNTIF($AZ$5:AZ7,AR$6:AR$132),0))} -> Multiplus | BA8: {=INDEX(AM$6:AM$161,MATCH(0,COUNTIF($BA$5:BA7,AM$6:AM$161),0))} -> 0.5 | BB8: {=INDEX(AQ$6:AQ$161,MATCH(0,COUNTIF($BB$5:BB7,AQ$6:AQ$161),0))} -> 48 | BC8: {=INDEX(AR$205:AR$236,MATCH(0,COUNTIF($BC$5:BC7,AR$205:AR$236),0))} -> Jinko_Lithium | BD8: {=INDEX(AM$205:AM$236,MATCH(0,COUNTIF($BD$5:BD7,AM$205:AM$236),0))} -> 5 | BE8: {=INDEX(AR$242:AR$254,MATCH(0,COUNTIF($BE$5:BE7,AR$242:AR$254),0))} -> Jinko_Solar_Panel | BL8: ='Customer Base'!$J$9*1000*0.8/$BO$8 -> 1.017 | BM8: =MOD('Customer Base'!$J$9*1000*0.8,$BO8) -> 68 | BN8: 70 | BO8: 4000
A9: =IF(AND('Customer Base'!D$8=12,'Customer Base'!D$13="Victron",'Customer Base'!E$13="Phoenix",'Customer Base'!D$14>0.5,'Customer Base'!D$14<=0.8),'Customer Base'!D$15,IF(AND('Customer Base'!D$7="Mini-Grid",'Customer Base'!D$8=12,'Customer Base'!F$13="Victron",'Customer Base'!F$14>0.5,'Customer Base'!F$14<=0.8),'Customer Base'!F$15,"")) | C9: Victron Phoenix Inverter 12/800 230V VE.Direct UK | D9: 256.46 | E9: 241.542 | F9: =$D9/1.219 -> 210.38556 | G9: =IFERROR(ROUNDUP(F9*'Customer Base'!$J$5,2),0) -> 3513.44 | H9: =$E9/1.219 -> 198.14766 | I9: =IFERROR(ROUNDUP(H9*'Customer Base'!$J$5,2),0) -> 3309.07 | J9: =ROUNDUP((M9/$L$4)*$L$3*3,-1) -> 2400 | K9: Western Region | L9: =J9/'Customer Base'!$J$5 -> 143.71257 | M9: 228 | N9: 4 | O9: =IF('Customer Base'!$I$15="MANUAL",IF(B9<>"",C9,""),IF('Customer Base'!$I$15="AUTOMATE",IF(A9<>"",C9,""),"")) | P9: DATA LOGGER RENTAL FROM 13-05-2022 TO 20-05-2022 | Q9: Delivery: Inverter is currently available. Batteries will be available by end of February | S9: Validity: 90 days from date of invoice | T9: Warranty: 2 Years for lead-acid batteries | U9: System Design: Grid-tied solar system for industrifal facility | W9: RESIDENTIAL | AD9: Bank Name: STANDARD CHARTERED BANK GHANA LIMITED | AE9: Account No: 0100106241600 (GHS) | AF9: Account No: 8701506241600 (USD) | AG9: Account Name: Tino Solutions Limited | AH9: Swift Code: SCBLGHACXXX | AI9: Sort Code: 020127 | AJ9: Bank Branch: Achimota Mall | AM9: 0.8 | AN9: 12/800 | AO9: =IF('Customer Base'!$I$15="MANUAL",IFERROR(AM9*B9,""),IF('Customer Base'!$I$15="AUTOMATE",IFERROR(AM9*A9,""),"")) | AQ9: 12 | AR9: Phoenix | AS9: 1 | AT9: =IF(AND(AR9=$AY$1,$AZ$1=AN9),BA$1,"") | AV9: =IF(AU9<>"",AU9,AT9) | AZ9: {=INDEX(AR$6:AR$132,MATCH(0,COUNTIF($AZ$5:AZ8,AR$6:AR$132),0))} -> Multiplus_II | BA9: {=INDEX(AM$6:AM$161,MATCH(0,COUNTIF($BA$5:BA8,AM$6:AM$161),0))} -> 0.8 | BB9: {=INDEX(AQ$6:AQ$161,MATCH(0,COUNTIF($BB$5:BB8,AQ$6:AQ$161),0))} -> 0 | BC9: {=INDEX(AR$205:AR$236,MATCH(0,COUNTIF($BC$5:BC8,AR$205:AR$236),0))} -> Huawei_Lithium | BD9: {=INDEX(AM$205:AM$236,MATCH(0,COUNTIF($BD$5:BD8,AM$205:AM$236),0))} -> 0 | BE9: {=INDEX(AR$242:AR$254,MATCH(0,COUNTIF($BE$5:BE8,AR$242:AR$254),0))} -> JA_Solar_Panel | BL9: ='Customer Base'!$J$9*1000*0.8/$BO$9 -> 0.83020408 | BM9: =MOD('Customer Base'!$J$9*1000*0.8,$BO9) -> 4068 | BN9: 85 | BO9: 4900
C10: Victron Phoenix Inverter 12/1200 230V VE.Direct UK | D10: 338.63 | E10: 318.946 | F10: =$D10/1.219 -> 277.79327 | G10: =IFERROR(ROUNDUP(F10*'Customer Base'!$J$5,2),0) -> 4639.15 | H10: =$E10/1.219 -> 261.64561 | I10: =IFERROR(ROUNDUP(H10*'Customer Base'!$J$5,2),0) -> 4369.49 | J10: =ROUNDUP((M10/$L$4)*$L$3*3,-1) -> 2400 | K10: Takoradi | L10: =J10/'Customer Base'!$J$5 -> 143.71257 | M10: 228 | N10: 5 | O10: =IF('Customer Base'!$I$15="MANUAL",IF(B10<>"",C10,""),IF('Customer Base'!$I$15="AUTOMATE",IF(A10<>"",C10,""),"")) | P10: VICTRON HYBRID SOLAR SYSTEM | U10: System Design: System Components for Installation by client | W10: NON-RESIDENTIAL | AD10: Bank Name: ZENITH BANK (GH) LTD | AE10: Account No: 6010184886 (GHS) | AF10: Account No: 6040100024 (USD) | AG10: Account Name: Tino Solutions Limited | AH10: Swift Code: ZEBLGHACXXX | AI10: Sort Code: 120101 | AJ10: Bank Branch: Premier Towers | AM10: 1.2 | AN10: 12/1200 VE.Direct | AO10: =IF('Customer Base'!$I$15="MANUAL",IFERROR(AM10*B10,""),IF('Customer Base'!$I$15="AUTOMATE",IFERROR(AM10*A10,""),"")) -> 0 | AQ10: 12 | AR10: Phoenix | AS10: 1 | AT10: =IF(AND(AR10=$AY$1,$AZ$1=AN10),BA$1,"") | AV10: =IF(AU10<>"",AU10,AT10) | AZ10: {=INDEX(AR$6:AR$132,MATCH(0,COUNTIF($AZ$5:AZ9,AR$6:AR$132),0))} -> Multiplus_II_GX | BA10: {=INDEX(AM$6:AM$161,MATCH(0,COUNTIF($BA$5:BA9,AM$6:AM$161),0))} -> 1.2 | BB10: {=INDEX(AQ$6:AQ$161,MATCH(0,COUNTIF($BB$5:BB9,AQ$6:AQ$161),0))} -> Grid-Tied | BC10: {=INDEX(AR$205:AR$236,MATCH(0,COUNTIF($BC$5:BC9,AR$205:AR$236),0))} -> Victron_AGM | BD10: {=INDEX(AM$205:AM$236,MATCH(0,COUNTIF($BD$5:BD9,AM$205:AM$236),0))} -> 15.4 | BE10: {=INDEX(AR$242:AR$254,MATCH(0,COUNTIF($BE$5:BE9,AR$242:AR$254),0))} -> Sharp_Solar_Panel | BL10: ='Customer Base'!$J$9*1000*0.8/$BO$10 -> 0.70137931 | BM10: =MOD('Customer Base'!$J$9*1000*0.8,$BO10) -> 4068 | BN10: 100 | BO10: 5800
C11: Victron Phoenix Inverter 24/250 230V VE.Direct UK | D11: 95.52 | E11: 91.85 | F11: =$D11/1.219 -> 78.359311 | G11: =IFERROR(ROUNDUP(F11*'Customer Base'!$J$5,2),0) -> 1308.61 | H11: =$E11/1.219 -> 75.348646 | I11: =IFERROR(ROUNDUP(H11*'Customer Base'!$J$5,2),0) -> 1258.33 | J11: =ROUNDUP((M11/$L$4)*$L$3*3,-1) -> 2400 | K11: Secondi | L11: =J11/'Customer Base'!$J$5 -> 143.71257 | M11: 228 | N11: 6 | O11: =IF('Customer Base'!$I$15="MANUAL",IF(B11<>"",C11,""),IF('Customer Base'!$I$15="AUTOMATE",IF(A11<>"",C11,""),"")) | P11: VICTRON OFF-GRID SOLAR SYSTEM | U11: System Design: System Upgrade | W11: SLT LV | AD11: Bank Name: UNITED BANK FOR AFRICA (GHANA) LTD | AE11: Account No: 00101312003503 (GHS) | AF11: Account No: 00101312002230 (USD) | AG11: Account Name: Tino Solutions Limited | AH11: Swift Code: STBGGHACXXX | AI11: Sort Code: 060101 | AJ11: Bank Branch: Heritage Tower | AM11: 0.25 | AN11: 24/250 | AO11: =IF('Customer Base'!$I$15="MANUAL",IFERROR(AM11*B11,""),IF('Customer Base'!$I$15="AUTOMATE",IFERROR(AM11*A11,""),"")) -> 0 | AQ11: 24 | AR11: Phoenix | AS11: 1 | AT11: =IF(AND(AR11=$AY$1,$AZ$1=AN11),BA$1,"") | AV11: =IF(AU11<>"",AU11,AT11) | AZ11: {=INDEX(AR$6:AR$132,MATCH(0,COUNTIF($AZ$5:AZ10,AR$6:AR$132),0))} -> Quattro | BA11: {=INDEX(AM$6:AM$161,MATCH(0,COUNTIF($BA$5:BA10,AM$6:AM$161),0))} -> 1.6 | BC11: {=INDEX(AR$205:AR$236,MATCH(0,COUNTIF($BC$5:BC10,AR$205:AR$236),0))} -> Victron_Gel | BD11: {=INDEX(AM$205:AM$236,MATCH(0,COUNTIF($BD$5:BD10,AM$205:AM$236),0))} -> 2.56 | BE11: {=INDEX(AR$242:AR$254,MATCH(0,COUNTIF($BE$5:BE10,AR$242:AR$254),0))} -> Victron_Solar_Panel
C12: Victron Phoenix Inverter 24/375 230V VE.Direct UK | D12: 126.42 | E12: 119.07 | F12: =$D12/1.219 -> 103.70796 | G12: =IFERROR(ROUNDUP(F12*'Customer Base'!$J$5,2),0) -> 1731.93 | H12: =$E12/1.219 -> 97.678425 | I12: =IFERROR(ROUNDUP(H12*'Customer Base'!$J$5,2),0) -> 1631.23 | J12: =ROUNDUP((M12/$L$4)*$L$3*3,-1) -> 8510 | K12: Upper East Region | L12: =J12/'Customer Base'!$J$5 -> 509.58084 | M12: 810 | N12: 7 | O12: =IF('Customer Base'!$I$15="MANUAL",IF(B12<>"",C12,""),IF('Customer Base'!$I$15="AUTOMATE",IF(A12<>"",C12,""),"")) | P12: GRID TIED SOLAR SYSTEM | U12: System Design: Solar System Relocation | W12: SLT MV | AD12: Bank Name: CONSOLIDATED BANK GHANA LTD | AE12: Account No: 0111302717161 (GHS) | AF12: Account No: 0111302717162 (USD) | AG12: Account Name: Tino Solutions Limited | AH12: Swift Code: CBGHGHACXXX | AI12: Sort Code: 340147 | AJ12: Bank Branch: Oxford Street Branch | AM12: 0.375 | AN12: 24/375 | AO12: =IF('Customer Base'!$I$15="MANUAL",IFERROR(AM12*B12,""),IF('Customer Base'!$I$15="AUTOMATE",IFERROR(AM12*A12,""),"")) -> 0 | AQ12: 24 | AR12: Phoenix | AS12: 1 | AT12: =IF(AND(AR12=$AY$1,$AZ$1=AN12),BA$1,"") | AV12: =IF(AU12<>"",AU12,AT12) | AZ12: {=INDEX(AR$6:AR$132,MATCH(0,COUNTIF($AZ$5:AZ11,AR$6:AR$132),0))} -> EasySolar | BA12: {=INDEX(AM$6:AM$161,MATCH(0,COUNTIF($BA$5:BA11,AM$6:AM$161),0))} -> 2 | BC12: {=INDEX(AR$205:AR$236,MATCH(0,COUNTIF($BC$5:BC11,AR$205:AR$236),0))} -> Hoppecke_OPzV | BD12: {=INDEX(AM$205:AM$236,MATCH(0,COUNTIF($BD$5:BD11,AM$205:AM$236),0))} -> 4.8 | BL12: =MIN(BL4:BL10) -> 0.70137931 | BM12: =MAX(BM4:BM10) -> 4068
A13: =IF(AND('Customer Base'!D$8=24,'Customer Base'!D$13="Victron",'Customer Base'!E$13="Phoenix",'Customer Base'!D$14>0,'Customer Base'!D$14<=0.5),'Customer Base'!D$15,IF(AND('Customer Base'!D$7="Mini-Grid",'Customer Base'!D$8=24,'Customer Base'!F$13="Victron",'Customer Base'!F$14>0,'Customer Base'!F$14<=0.5),'Customer Base'!F$15,"")) | C13: Victron Phoenix Inverter 24/500 230V VE.Direct UK | D13: 158.03 | E13: 148.85 | F13: =$D13/1.219 -> 129.63905 | G13: =IFERROR(ROUNDUP(F13*'Customer Base'!$J$5,2),0) -> 2164.98 | H13: =$E13/1.219 -> 122.10829 | I13: =IFERROR(ROUNDUP(H13*'Customer Base'!$J$5,2),0) -> 2039.21 | J13: =ROUNDUP((M13/$L$4)*$L$3*3,-1) -> 8510 | K13: Bolgatanga | L13: =J13/'Customer Base'!$J$5 -> 509.58084 | M13: 810 | N13: 8 | O13: =IF('Customer Base'!$I$15="MANUAL",IF(B13<>"",C13,""),IF('Customer Base'!$I$15="AUTOMATE",IF(A13<>"",C13,""),"")) | P13: TROUBLESHOOTING OF FAULT ON SOLAR SYSTEM | U13: System Design: Solar System Relocation and Upgrade | W13: SLT HV | AD13: Bank Name: ECOBANK (GH) LTD | AE13: Account No: 1441002237313 (GHS) | AF13: Account No: 3441002198840 (USD) | AG13: Account Name: Tino Solutions Limited | AH13: Swift Code: ECOCGHACXXX | AI13: Sort Code: 130111 | AJ13: Bank Branch: Abeka Lapaz | AM13: 0.5 | AN13: 24/500 | AO13: =IF('Customer Base'!$I$15="MANUAL",IFERROR(AM13*B13,""),IF('Customer Base'!$I$15="AUTOMATE",IFERROR(AM13*A13,""),"")) | AQ13: 24 | AR13: Phoenix | AS13: 1 | AT13: =IF(AND(AR13=$AY$1,$AZ$1=AN13),BA$1,"") | AV13: =IF(AU13<>"",AU13,AT13) | AZ13: {=INDEX(AR$6:AR$132,MATCH(0,COUNTIF($AZ$5:AZ12,AR$6:AR$132),0))} -> EasySolar_II | BA13: {=INDEX(AM$6:AM$161,MATCH(0,COUNTIF($BA$5:BA12,AM$6:AM$161),0))} -> 3 | BC13: {=INDEX(AR$205:AR$236,MATCH(0,COUNTIF($BC$5:BC12,AR$205:AR$236),0))} -> Hoppecke_Lead_Acid | BD13: {=INDEX(AM$205:AM$236,MATCH(0,COUNTIF($BD$5:BD12,AM$205:AM$236),0))} -> 0.096
A14: =IF(AND('Customer Base'!D$8=24,'Customer Base'!D$13="Victron",'Customer Base'!E$13="Phoenix",'Customer Base'!D$14>0.5,'Customer Base'!D$14<=0.8),'Customer Base'!D$15,IF(AND('Customer Base'!D$7="Mini-Grid",'Customer Base'!D$8=24,'Customer Base'!F$13="Victron",'Customer Base'!F$14>0.5,'Customer Base'!F$14<=0.8),'Customer Base'!F$15,"")) | C14: Victron Phoenix Inverter 24/800 230V VE.Direct UK | D14: 256.46 | E14: 241.54 | F14: =$D14/1.219 -> 210.38556 | G14: =IFERROR(ROUNDUP(F14*'Customer Base'!$J$5,2),0) -> 3513.44 | H14: =$E14/1.219 -> 198.14602 | I14: =IFERROR(ROUNDUP(H14*'Customer Base'!$J$5,2),0) -> 3309.04 | J14: =ROUNDUP((M14/$L$4)*$L$3*3,-1) -> 900 | K14: Eastern Region | L14: =J14/'Customer Base'!$J$5 -> 53.892216 | M14: 85 | N14: 9 | O14: =IF('Customer Base'!$I$15="MANUAL",IF(B14<>"",C14,""),IF('Customer Base'!$I$15="AUTOMATE",IF(A14<>"",C14,""),"")) | P14: SOLAR SYSTEM UPGRADE | U14: System Design: Removal and Reinstallation of Solar System | W14: SLT Steel Companies | AD14: Bank Name: FIDELITY BANK GHANA LIMITED | AE14: Account No: 1050028224118 (GHS) | AF14: Account No: 1951028224113 (USD) | AG14: Account Name: Tino Solutions Limited | AH14: Swift Code: FBLIGHACXXX | AI14: Sort Code: 240118 | AJ14: Bank Branch: Adenta | AM14: 0.8 | AN14: 24/800 | AO14: =IF('Customer Base'!$I$15="MANUAL",IFERROR(AM14*B14,""),IF('Customer Base'!$I$15="AUTOMATE",IFERROR(AM14*A14,""),"")) | AQ14: 24 | AR14: Phoenix | AS14: 1 | AT14: =IF(AND(AR14=$AY$1,$AZ$1=AN14),BA$1,"") | AV14: =IF(AU14<>"",AU14,AT14) | AZ14: {=INDEX(AR$6:AR$132,MATCH(0,COUNTIF($AZ$5:AZ13,AR$6:AR$132),0))} -> Phocos_H | BA14: {=INDEX(AM$6:AM$161,MATCH(0,COUNTIF($BA$5:BA13,AM$6:AM$161),0))} -> 5 | BC14: {=INDEX(AR$205:AR$236,MATCH(0,COUNTIF($BC$5:BC13,AR$205:AR$236),0))} -> #N/A | BD14: {=INDEX(AM$205:AM$236,MATCH(0,COUNTIF($BD$5:BD13,AM$205:AM$236),0))} -> 0.168 | BN14: =VLOOKUP(BL12,BL4:BO10,3,FALSE) -> 100 | BO14: =VLOOKUP(BM12,BM4:BO10,2,FALSE) -> 85
C15: Victron Phoenix Inverter 24/1200 230V VE.Direct UK | D15: 338.63 | E15: 318.95 | F15: =$D15/1.219 -> 277.79327 | G15: =IFERROR(ROUNDUP(F15*'Customer Base'!$J$5,2),0) -> 4639.15 | H15: =$E15/1.219 -> 261.64889 | I15: =IFERROR(ROUNDUP(H15*'Customer Base'!$J$5,2),0) -> 4369.54 | J15: =ROUNDUP((M15/$L$4)*$L$3*3,-1) -> 900 | K15: Koforidua | L15: =J15/'Customer Base'!$J$5 -> 53.892216 | M15: 85 | N15: 10 | O15: =IF('Customer Base'!$I$15="MANUAL",IF(B15<>"",C15,""),IF('Customer Base'!$I$15="AUTOMATE",IF(A15<>"",C15,""),"")) | P15: SOLAR SYSTEM RELOCATION | U15: System Design: Solar system to supply power to residential facility | W15: SLT HV Mines | AD15: Bank Name: CAL BANK GHANA LIMITED | AE15: Account No: 1400007916096 (GHS) | AF15: Account No: 14000079000234 (USD) | AG15: Account Name: Tino Solutions Limited | AH15: Swift Code: ACCCGHACXXX | AI15: Sort Code: 140101 | AJ15: Bank Branch: Independence Avenue | AM15: 1.2 | AN15: 24/1200 | AO15: =IF('Customer Base'!$I$15="MANUAL",IFERROR(AM15*B15,""),IF('Customer Base'!$I$15="AUTOMATE",IFERROR(AM15*A15,""),"")) -> 0 | AQ15: 24 | AR15: Phoenix | AS15: 1 | AT15: =IF(AND(AR15=$AY$1,$AZ$1=AN15),BA$1,"") | AV15: =IF(AU15<>"",AU15,AT15) | AZ15: {=INDEX(AR$6:AR$132,MATCH(0,COUNTIF($AZ$5:AZ14,AR$6:AR$132),0))} -> Phocos_B | BA15: {=INDEX(AM$6:AM$161,MATCH(0,COUNTIF($BA$5:BA14,AM$6:AM$161),0))} -> 0 | BC15: {=INDEX(AR$205:AR$236,MATCH(0,COUNTIF($BC$5:BC14,AR$205:AR$236),0))} -> #N/A | BD15: {=INDEX(AM$205:AM$236,MATCH(0,COUNTIF($BD$5:BD14,AM$205:AM$236),0))} -> 0.264
C16: Victron Phoenix Inverter 48/250 230V VE.Direct UK | D16: 95.52 | E16: 91.854 | F16: =$D16/1.219 -> 78.359311 | G16: =IFERROR(ROUNDUP(F16*'Customer Base'!$J$5,2),0) -> 1308.61 | H16: =$E16/1.219 -> 75.351928 | I16: =IFERROR(ROUNDUP(H16*'Customer Base'!$J$5,2),0) -> 1258.38 | J16: =ROUNDUP((M16/$L$4)*$L$3*3,-1) -> 1200 | K16: Central Region | L16: =J16/'Customer Base'!$J$5 -> 71.856287 | M16: 114 | N16: 11 | O16: =IF('Customer Base'!$I$15="MANUAL",IF(B16<>"",C16,""),IF('Customer Base'!$I$15="AUTOMATE",IF(A16<>"",C16,""),"")) | P16: REMOVAL OF SOLAR SYSTEM COMPONENTS AND REINSTALLATION | AD16: Bank Name: ABSA BANK GHANA LIMITED | AE16: Account No: 0000001075713 (GHS) | AF16: Account No: 0000001504475 (USD) | AG16: Account Name: Tino Solutions Limited | AH16: Swift Code: BARCGHACXXX | AI16: Sort Code: 030114 | AJ16: Bank Branch: Ring Road Central | AM16: 0.25 | AN16: 48/250 | AO16: =IF('Customer Base'!$I$15="MANUAL",IFERROR(AM16*B16,""),IF('Customer Base'!$I$15="AUTOMATE",IFERROR(AM16*A16,""),"")) -> 0 | AQ16: 48 | AR16: Phoenix | AS16: 1 | AT16: =IF(AND(AR16=$AY$1,$AZ$1=AN16),BA$1,"") | AV16: =IF(AU16<>"",AU16,AT16) | AZ16: {=INDEX(AR$6:AR$132,MATCH(0,COUNTIF($AZ$5:AZ15,AR$6:AR$132),0))} -> Deye | BA16: {=INDEX(AM$6:AM$161,MATCH(0,COUNTIF($BA$5:BA15,AM$6:AM$161),0))} -> 6 | BC16: {=INDEX(AR$205:AR$236,MATCH(0,COUNTIF($BC$5:BC15,AR$205:AR$236),0))} -> #N/A | BD16: {=INDEX(AM$205:AM$236,MATCH(0,COUNTIF($BD$5:BD15,AM$205:AM$236),0))} -> 0.456
C17: Victron Phoenix Inverter 48/375 230V VE.Direct UK | D17: 126.42 | E17: 119.07 | F17: =$D17/1.219 -> 103.70796 | G17: =IFERROR(ROUNDUP(F17*'Customer Base'!$J$5,2),0) -> 1731.93 | H17: =$E17/1.219 -> 97.678425 | I17: =IFERROR(ROUNDUP(H17*'Customer Base'!$J$5,2),0) -> 1631.23 | J17: =ROUNDUP((M17/$L$4)*$L$3*3,-1) -> 1200 | K17: Cape Coast | L17: =J17/'Customer Base'!$J$5 -> 71.856287 | M17: 114 | N17: 12 | O17: =IF('Customer Base'!$I$15="MANUAL",IF(B17<>"",C17,""),IF('Customer Base'!$I$15="AUTOMATE",IF(A17<>"",C17,""),"")) | P17: DECOMMISSIONING OF SOLAR SYSTEM | AM17: 0.375 | AN17: 48/375 | AO17: =IF('Customer Base'!$I$15="MANUAL",IFERROR(AM17*B17,""),IF('Customer Base'!$I$15="AUTOMATE",IFERROR(AM17*A17,""),"")) -> 0 | AQ17: 48 | AR17: Phoenix | AS17: 1 | AT17: =IF(AND(AR17=$AY$1,$AZ$1=AN17),BA$1,"") | AV17: =IF(AU17<>"",AU17,AT17) | AZ17: {=INDEX(AR$6:AR$132,MATCH(0,COUNTIF($AZ$5:AZ16,AR$6:AR$132),0))} -> Huawei | BA17: {=INDEX(AM$6:AM$161,MATCH(0,COUNTIF($BA$5:BA16,AM$6:AM$161),0))} -> 8 | BD17: {=INDEX(AM$205:AM$236,MATCH(0,COUNTIF($BD$5:BD16,AM$205:AM$236),0))} -> 0.72
A18: =IF(AND('Customer Base'!D$8=48,'Customer Base'!D$13="Victron",'Customer Base'!E$13="Phoenix",'Customer Base'!D$14>0,'Customer Base'!D$14<=0.5),'Customer Base'!D$15,IF(AND('Customer Base'!D$7="Mini-Grid",'Customer Base'!D$8=48,'Customer Base'!F$13="Victron",'Customer Base'!F$14>0,'Customer Base'!F$14<=0.5),'Customer Base'!F$15,"")) | C18: Victron Phoenix Inverter 48/500 230V VE.Direct UK | D18: 158.03 | E18: 148.846 | F18: =$D18/1.219 -> 129.63905 | G18: =IFERROR(ROUNDUP(F18*'Customer Base'!$J$5,2),0) -> 2164.98 | H18: =$E18/1.219 -> 122.105 | I18: =IFERROR(ROUNDUP(H18*'Customer Base'!$J$5,2),0) -> 2039.16 | J18: =ROUNDUP((M18/$L$4)*$L$3*3,-1) -> 2840 | K18: Ashanti Region | L18: =J18/'Customer Base'!$J$5 -> 170.05988 | M18: 270 | N18: 13 | O18: =IF('Customer Base'!$I$15="MANUAL",IF(B18<>"",C18,""),IF('Customer Base'!$I$15="AUTOMATE",IF(A18<>"",C18,""),"")) | P18: MAINTENANCE OF SOLAR SYSTEM | AM18: 0.5 | AN18: 48/500 | AO18: =IF('Customer Base'!$I$15="MANUAL",IFERROR(AM18*B18,""),IF('Customer Base'!$I$15="AUTOMATE",IFERROR(AM18*A18,""),"")) | AQ18: 48 | AR18: Phoenix | AS18: 1 | AT18: =IF(AND(AR18=$AY$1,$AZ$1=AN18),BA$1,"") | AV18: =IF(AU18<>"",AU18,AT18) | AZ18: {=INDEX(AR$6:AR$132,MATCH(0,COUNTIF($AZ$5:AZ17,AR$6:AR$132),0))} -> Galvo | BA18: {=INDEX(AM$6:AM$161,MATCH(0,COUNTIF($BA$5:BA17,AM$6:AM$161),0))} -> 10 | BD18: {=INDEX(AM$205:AM$236,MATCH(0,COUNTIF($BD$5:BD17,AM$205:AM$236),0))} -> 1.08 | BM18: =MIN(BN14:BO14) -> 85
A19: =IF(AND('Customer Base'!D$8=48,'Customer Base'!D$13="Victron",'Customer Base'!E$13="Phoenix",'Customer Base'!D$14>0.5,'Customer Base'!D$14<=0.8),'Customer Base'!D$15,IF(AND('Customer Base'!D$7="Mini-Grid",'Customer Base'!D$8=48,'Customer Base'!F$13="Victron",'Customer Base'!F$14>0.5,'Customer Base'!F$14<=0.8),'Customer Base'!F$15,"")) | C19: Victron Phoenix Inverter 48/800 230V VE.Direct UK | D19: 256.46 | E19: 241.542 | F19: =$D19/1.219 -> 210.38556 | G19: =IFERROR(ROUNDUP(F19*'Customer Base'!$J$5,2),0) -> 3513.44 | H19: =$E19/1.219 -> 198.14766 | I19: =IFERROR(ROUNDUP(H19*'Customer Base'!$J$5,2),0) -> 3309.07 | J19: =ROUNDUP((M19/$L$4)*$L$3*3,-1) -> 2840 | K19: Kumasi | L19: =J19/'Customer Base'!$J$5 -> 170.05988 | M19: 270 | N19: 14 | O19: =IF('Customer Base'!$I$15="MANUAL",IF(B19<>"",C19,""),IF('Customer Base'!$I$15="AUTOMATE",IF(A19<>"",C19,""),"")) | P19: SOLAR SYSTEM SUPPORT SERVICE | AM19: 0.8 | AN19: 48/800 | AO19: =IF('Customer Base'!$I$15="MANUAL",IFERROR(AM19*B19,""),IF('Customer Base'!$I$15="AUTOMATE",IFERROR(AM19*A19,""),"")) | AQ19: 48 | AR19: Phoenix | AS19: 1 | AT19: =IF(AND(AR19=$AY$1,$AZ$1=AN19),BA$1,"") | AV19: =IF(AU19<>"",AU19,AT19) | AZ19: {=INDEX(AR$6:AR$132,MATCH(0,COUNTIF($AZ$5:AZ18,AR$6:AR$132),0))} -> Primo | BA19: {=INDEX(AM$6:AM$161,MATCH(0,COUNTIF($BA$5:BA18,AM$6:AM$161),0))} -> 15 | BD19: {=INDEX(AM$205:AM$236,MATCH(0,COUNTIF($BD$5:BD18,AM$205:AM$236),0))} -> 1.32
A20: =IF(AND('Customer Base'!D$8=48,'Customer Base'!D$13="Victron",'Customer Base'!E$13="Phoenix",'Customer Base'!D$14>0.8,'Customer Base'!D$14<=1.2),'Customer Base'!D$15,IF(AND('Customer Base'!D$7="Mini-Grid",'Customer Base'!D$8=48,'Customer Base'!F$13="Victron",'Customer Base'!F$14>0.8,'Customer Base'!F$14<=1.2),'Customer Base'!F$15,"")) | C20: Victron Phoenix Inverter 48/1200 230V VE.Direct UK | D20: 338.63 | E20: 318.946 | F20: =$D20/1.219 -> 277.79327 | G20: =IFERROR(ROUNDUP(F20*'Customer Base'!$J$5,2),0) -> 4639.15 | H20: =$E20/1.219 -> 261.64561 | I20: =IFERROR(ROUNDUP(H20*'Customer Base'!$J$5,2),0) -> 4369.49 | J20: =ROUNDUP((M20/$L$4)*$L$3*3,-1) -> 1950 | K20: Volta Region | L20: =J20/'Customer Base'!$J$5 -> 116.76647 | M20: 185 | N20: 15 | O20: =IF('Customer Base'!$I$15="MANUAL",IF(B20<>"",C20,""),IF('Customer Base'!$I$15="AUTOMATE",IF(A20<>"",C20,""),"")) | P20: SYSTEM COMPONENT COSTS | AM20: 1.2 | AN20: 48/1200 | AO20: =IF('Customer Base'!$I$15="MANUAL",IFERROR(AM20*B20,""),IF('Customer Base'!$I$15="AUTOMATE",IFERROR(AM20*A20,""),"")) | AQ20: 48 | AR20: Phoenix | AS20: 1 | AT20: =IF(AND(AR20=$AY$1,$AZ$1=AN20),BA$1,"") | AV20: =IF(AU20<>"",AU20,AT20) | AZ20: {=INDEX(AR$6:AR$132,MATCH(0,COUNTIF($AZ$5:AZ19,AR$6:AR$132),0))} -> Symo | BA20: {=INDEX(AM$6:AM$161,MATCH(0,COUNTIF($BA$5:BA19,AM$6:AM$161),0))} -> 16 | BD20: {=INDEX(AM$205:AM$236,MATCH(0,COUNTIF($BD$5:BD19,AM$205:AM$236),0))} -> 2.64
A21: =IF(AND('Customer Base'!D$8=48,'Customer Base'!D$13="Victron",'Customer Base'!E$13="Phoenix",'Customer Base'!D$14>1.2,'Customer Base'!D$14<=1.6),'Customer Base'!D$15,IF(AND('Customer Base'!D$7="Mini-Grid",'Customer Base'!D$8=48,'Customer Base'!F$13="Victron",'Customer Base'!F$14>1.2,'Customer Base'!F$14<=1.6),'Customer Base'!F$15,"")) | C21: Victron Phoenix Inverter 48/1600 230V Smart | D21: 544.52 | E21: 512.86 | F21: =$D21/1.219 -> 446.69401 | G21: =IFERROR(ROUNDUP(F21*'Customer Base'!$J$5,2),0) -> 7459.79 | H21: =$E21/1.219 -> 420.7219 | I21: =IFERROR(ROUNDUP(H21*'Customer Base'!$J$5,2),0) -> 7026.06 | J21: =ROUNDUP((M21/$L$4)*$L$3*3,-1) -> 1950 | K21: Ho | L21: =J21/'Customer Base'!$J$5 -> 116.76647 | M21: 185 | N21: 16 | O21: =IF('Customer Base'!$I$15="MANUAL",IF(B21<>"",C21,""),IF('Customer Base'!$I$15="AUTOMATE",IF(A21<>"",C21,""),"")) | P21: BACKUP SYSTEM | AM21: 1.6 | AN21: 48/1600 | AO21: =IF('Customer Base'!$I$15="MANUAL",IFERROR(AM21*B21,""),IF('Customer Base'!$I$15="AUTOMATE",IFERROR(AM21*A21,""),"")) | AQ21: 48 | AR21: Phoenix | AS21: 1 | AT21: =IF(AND(AR21=$AY$1,$AZ$1=AN21),BA$1,"") | AV21: =IF(AU21<>"",AU21,AT21) | AZ21: {=INDEX(AR$6:AR$132,MATCH(0,COUNTIF($AZ$5:AZ20,AR$6:AR$132),0))} -> Eco | BA21: {=INDEX(AM$6:AM$161,MATCH(0,COUNTIF($BA$5:BA20,AM$6:AM$161),0))} -> 12 | BD21: {=INDEX(AM$205:AM$236,MATCH(0,COUNTIF($BD$5:BD20,AM$205:AM$236),0))} -> 2.4
A22: =IF(AND('Customer Base'!D$8=48,'Customer Base'!D$13="Victron",'Customer Base'!E$13="Phoenix",'Customer Base'!D$14>1.6,'Customer Base'!D$14<=2),'Customer Base'!D$15,IF(AND('Customer Base'!D$7="Mini-Grid",'Customer Base'!D$8=48,'Customer Base'!F$13="Victron",'Customer Base'!F$14>1.6,'Customer Base'!F$14<=2),'Customer Base'!F$15,"")) | C22: Victron Phoenix Inverter 48/2000 230V Smart | D22: 649.27 | E22: 611.518 | F22: =$D22/1.219 -> 532.6251 | G22: =IFERROR(ROUNDUP(F22*'Customer Base'!$J$5,2),0) -> 8894.84 | H22: =$E22/1.219 -> 501.65546 | I22: =IFERROR(ROUNDUP(H22*'Customer Base'!$J$5,2),0) -> 8377.65 | J22: =ROUNDUP((M22/$L$4)*$L$3*3,-1) -> 7480 | K22: Upper West Region | L22: =J22/'Customer Base'!$J$5 -> 447.90419 | M22: 712 | N22: 17 | O22: =IF('Customer Base'!$I$15="MANUAL",IF(B22<>"",C22,""),IF('Customer Base'!$I$15="AUTOMATE",IF(A22<>"",C22,""),"")) | P22: SOLAR STREET LIGHTS | AM22: 2 | AN22: 48/2000 | AO22: =IF('Customer Base'!$I$15="MANUAL",IFERROR(AM22*B22,""),IF('Customer Base'!$I$15="AUTOMATE",IFERROR(AM22*A22,""),"")) | AQ22: 48 | AR22: Phoenix | AS22: 1 | AT22: =IF(AND(AR22=$AY$1,$AZ$1=AN22),BA$1,"") | AV22: =IF(AU22<>"",AU22,AT22) | AZ22: {=INDEX(AR$6:AR$132,MATCH(0,COUNTIF($AZ$5:AZ21,AR$6:AR$132),0))} -> Verto | BA22: {=INDEX(AM$6:AM$161,MATCH(0,COUNTIF($BA$5:BA21,AM$6:AM$161),0))} -> 20 | BD22: {=INDEX(AM$205:AM$236,MATCH(0,COUNTIF($BD$5:BD21,AM$205:AM$236),0))} -> 26.3
A23: =IF(AND('Customer Base'!D$8=48,'Customer Base'!D$13="Victron",'Customer Base'!E$13="Phoenix",'Customer Base'!D$14>2,'Customer Base'!D$14<=3),'Customer Base'!D$15,IF(AND('Customer Base'!D$7="Mini-Grid",'Customer Base'!D$8=48,'Customer Base'!F$13="Victron",'Customer Base'!F$14>2,'Customer Base'!F$14<=3),'Customer Base'!F$15,"")) | C23: Victron Phoenix Inverter 48/3000 230V Smart | D23: 921.95 | E23: 868.352 | F23: =$D23/1.219 -> 756.31665 | G23: =IFERROR(ROUNDUP(F23*'Customer Base'!$J$5,2),0) -> 12630.49 | H23: =$E23/1.219 -> 712.34783 | I23: =IFERROR(ROUNDUP(H23*'Customer Base'!$J$5,2),0) -> 11896.21 | J23: =ROUNDUP((M23/$L$4)*$L$3*3,-1) -> 7480 | K23: Wa | L23: =J23/'Customer Base'!$J$5 -> 447.90419 | M23: 712 | N23: 18 | O23: =IF('Customer Base'!$I$15="MANUAL",IF(B23<>"",C23,""),IF('Customer Base'!$I$15="AUTOMATE",IF(A23<>"",C23,""),"")) | P23: SOLAR DC WATER PUMP PROJECT | AM23: 3 | AN23: 48/3000 | AO23: =IF('Customer Base'!$I$15="MANUAL",IFERROR(AM23*B23,""),IF('Customer Base'!$I$15="AUTOMATE",IFERROR(AM23*A23,""),"")) | AQ23: 48 | AR23: Phoenix | AS23: 1 | AT23: =IF(AND(AR23=$AY$1,$AZ$1=AN23),BA$1,"") | AV23: =IF(AU23<>"",AU23,AT23) | AZ23: {=INDEX(AR$6:AR$132,MATCH(0,COUNTIF($AZ$5:AZ22,AR$6:AR$132),0))} -> Tauro | BA23: {=INDEX(AM$6:AM$161,MATCH(0,COUNTIF($BA$5:BA22,AM$6:AM$161),0))} -> 30 | BD23: {=INDEX(AM$205:AM$236,MATCH(0,COUNTIF($BD$5:BD22,AM$205:AM$236),0))} -> 1.2
A24: =IF(AND('Customer Base'!D$8=48,'Customer Base'!D$13="Victron",'Customer Base'!E$13="Phoenix",'Customer Base'!D$14>3,'Customer Base'!D$14<=5),'Customer Base'!D$15,IF(AND('Customer Base'!D$7="Mini-Grid",'Customer Base'!D$8=48,'Customer Base'!F$13="Victron",'Customer Base'!F$14>3,'Customer Base'!F$14<=5),'Customer Base'!F$15,"")) | C24: Victron Phoenix Inverter 48/5000 230V Smart | D24: 1381.59 | E24: 1301.265 | F24: =$D24/1.219 -> 1133.3798 | G24: =IFERROR(ROUNDUP(F24*'Customer Base'!$J$5,2),0) -> 18927.45 | H24: =$E24/1.219 -> 1067.4856 | I24: =IFERROR(ROUNDUP(H24*'Customer Base'!$J$5,2),0) -> 17827.02 | J24: =ROUNDUP((M24/$L$4)*$L$3*3,-1) -> 4200 | K24: Bono Region | L24: =J24/'Customer Base'!$J$5 -> 251.49701 | M24: 400 | N24: 19 | O24: =IF('Customer Base'!$I$15="MANUAL",IF(B24<>"",C24,""),IF('Customer Base'!$I$15="AUTOMATE",IF(A24<>"",C24,""),"")) | AM24: 5 | AN24: 48/5000 | AO24: =IF('Customer Base'!$I$15="MANUAL",IFERROR(AM24*B24,""),IF('Customer Base'!$I$15="AUTOMATE",IFERROR(AM24*A24,""),"")) | AQ24: 48 | AR24: Phoenix | AS24: 1 | AT24: =IF(AND(AR24=$AY$1,$AZ$1=AN24),BA$1,"") | AV24: =IF(AU24<>"",AU24,AT24) | AZ24: {=INDEX(AR$6:AR$132,MATCH(0,COUNTIF($AZ$5:AZ23,AR$6:AR$132),0))} -> Gen_24_Primo | BA24: {=INDEX(AM$6:AM$161,MATCH(0,COUNTIF($BA$5:BA23,AM$6:AM$161),0))} -> 40 | BD24: {=INDEX(AM$205:AM$236,MATCH(0,COUNTIF($BD$5:BD23,AM$205:AM$236),0))} -> 1.8
F25: =$D25/1.219 -> 0 | G25: =IFERROR(ROUNDUP(F25*'Customer Base'!$J$5,2),0) -> 0 | H25: =$E25/1.219 -> 0 | I25: =IFERROR(ROUNDUP(H25*'Customer Base'!$J$5,2),0) -> 0 | J25: =ROUNDUP((M25/$L$4)*$L$3*3,-1) -> 4200 | K25: Sunyani | L25: =J25/'Customer Base'!$J$5 -> 251.49701 | M25: 400 | N25: 20 | O25: =IF('Customer Base'!$I$15="MANUAL",IF(B25<>"",C25,""),IF('Customer Base'!$I$15="AUTOMATE",IF(A25<>"",C25,""),"")) | AO25: =IF('Customer Base'!$I$15="MANUAL",IFERROR(AM25*B25,""),IF('Customer Base'!$I$15="AUTOMATE",IFERROR(AM25*A25,""),"")) -> 0 | AT25: =IF(AND(AR25=$AY$1,$AZ$1=AN25),BA$1,"") | AV25: =IF(AU25<>"",AU25,AT25) | BA25: {=INDEX(AM$6:AM$161,MATCH(0,COUNTIF($BA$5:BA24,AM$6:AM$161),0))} -> 50 | BD25: {=INDEX(AM$205:AM$236,MATCH(0,COUNTIF($BD$5:BD24,AM$205:AM$236),0))} -> 3
A26: =IF(AND('Customer Base'!D$8=12,'Customer Base'!D$13="Victron",'Customer Base'!E$13="Multiplus",'Customer Base'!D$14>0,'Customer Base'!D$14<=0.5),'Customer Base'!D$15,IF(AND('Customer Base'!D$7="Mini-Grid",'Customer Base'!D$8=12,'Customer Base'!F$13="Victron",'Customer Base'!F$14>0,'Customer Base'!F$14<=0.5),'Customer Base'!F$15,"")) | C26: Victron MultiPlus 12/500/20-16 230V VE.Bus | D26: 261.87 | E26: 246.645 | F26: =$D26/1.219 -> 214.82363 | G26: =IFERROR(ROUNDUP(F26*'Customer Base'!$J$5,2),0) -> 3587.56 | H26: =$E26/1.219 -> 202.33388 | I26: =IFERROR(ROUNDUP(H26*'Customer Base'!$J$5,2),0) -> 3378.98 | J26: =ROUNDUP((M26/$L$4)*$L$3*3,-1) -> 4070 | K26: Ahafo Region | L26: =J26/'Customer Base'!$J$5 -> 243.71257 | M26: 387 | N26: 21 | O26: =IF('Customer Base'!$I$15="MANUAL",IF(B26<>"",C26,""),IF('Customer Base'!$I$15="AUTOMATE",IF(A26<>"",C26,""),"")) | AM26: 0.5 | AN26: 12/500 | AO26: =IF('Customer Base'!$I$15="MANUAL",IFERROR(AM26*B26,""),IF('Customer Base'!$I$15="AUTOMATE",IFERROR(AM26*A26,""),"")) | AQ26: 12 | AR26: Multiplus | AS26: 1 | AT26: =IF(AND(AR26=$AY$1,$AZ$1=AN26),BA$1,"") | AV26: =IF(AU26<>"",AU26,AT26) | AW26: 20 | BA26: {=INDEX(AM$6:AM$161,MATCH(0,COUNTIF($BA$5:BA25,AM$6:AM$161),0))} -> 8.2 | BD26: {=INDEX(AM$205:AM$236,MATCH(0,COUNTIF($BD$5:BD25,AM$205:AM$236),0))} -> #N/A
A27: =IF(AND('Customer Base'!D$8=12,'Customer Base'!D$13="Victron",'Customer Base'!E$13="Multiplus",'Customer Base'!D$14>0.5,'Customer Base'!D$14<=0.8),'Customer Base'!D$15,IF(AND('Customer Base'!D$7="Mini-Grid",'Customer Base'!D$8=12,'Customer Base'!F$13="Victron",'Customer Base'!F$14>0.5,'Customer Base'!F$14<=0.8),'Customer Base'!F$15,"")) | C27: Victron MultiPlus 12/800/35-16 230V VE.Bus | D27: 307.91 | E27: 290.012 | F27: =$D27/1.219 -> 252.59229 | G27: =IFERROR(ROUNDUP(F27*'Customer Base'!$J$5,2),0) -> 4218.3 | H27: =$E27/1.219 -> 237.90976 | I27: =IFERROR(ROUNDUP(H27*'Customer Base'!$J$5,2),0) -> 3973.1 | J27: =ROUNDUP((M27/$L$4)*$L$3*3,-1) -> 4070 | K27: Goaso | L27: =J27/'Customer Base'!$J$5 -> 243.71257 | M27: 387 | N27: 22 | O27: =IF('Customer Base'!$I$15="MANUAL",IF(B27<>"",C27,""),IF('Customer Base'!$I$15="AUTOMATE",IF(A27<>"",C27,""),"")) | AM27: 0.8 | AN27: 12/800 | AO27: =IF('Customer Base'!$I$15="MANUAL",IFERROR(AM27*B27,""),IF('Customer Base'!$I$15="AUTOMATE",IFERROR(AM27*A27,""),"")) | AQ27: 12 | AR27: Multiplus | AS27: 1 | AT27: =IF(AND(AR27=$AY$1,$AZ$1=AN27),BA$1,"") | AV27: =IF(AU27<>"",AU27,AT27) | AW27: 35 | BA27: {=INDEX(AM$6:AM$161,MATCH(0,COUNTIF($BA$5:BA26,AM$6:AM$161),0))} -> 25 | BD27: {=INDEX(AM$205:AM$236,MATCH(0,COUNTIF($BD$5:BD26,AM$205:AM$236),0))} -> #N/A
A28: =IF(AND('Customer Base'!D$8=12,'Customer Base'!D$13="Victron",'Customer Base'!E$13="Multiplus",'Customer Base'!D$14>0.8,'Customer Base'!D$14<=1.2),'Customer Base'!D$15,IF(AND('Customer Base'!D$7="Mini-Grid",'Customer Base'!D$8=12,'Customer Base'!F$13="Victron",'Customer Base'!F$14>0.8,'Customer Base'!F$14<=1.2),'Customer Base'!F$15,"")) | C28: Victron MultiPlus 12/1200/50-16 230V VE.Bus | D28: 429.83 | E28: 404.838 | F28: =$D28/1.219 -> 352.6087 | G28: =IFERROR(ROUNDUP(F28*'Customer Base'!$J$5,2),0) -> 5888.57 | H28: =$E28/1.219 -> 332.10664 | I28: =IFERROR(ROUNDUP(H28*'Customer Base'!$J$5,2),0) -> 5546.19 | J28: =ROUNDUP((M28/$L$4)*$L$3*3,-1) -> 3590 | K28: Oti Region | L28: =J28/'Customer Base'!$J$5 -> 214.97006 | M28: 341 | N28: 23 | O28: =IF('Customer Base'!$I$15="MANUAL",IF(B28<>"",C28,""),IF('Customer Base'!$I$15="AUTOMATE",IF(A28<>"",C28,""),"")) | AM28: 1.2 | AN28: 12/1200 | AO28: =IF('Customer Base'!$I$15="MANUAL",IFERROR(AM28*B28,""),IF('Customer Base'!$I$15="AUTOMATE",IFERROR(AM28*A28,""),"")) | AQ28: 12 | AR28: Multiplus | AS28: 1 | AT28: =IF(AND(AR28=$AY$1,$AZ$1=AN28),BA$1,"") | AV28: =IF(AU28<>"",AU28,AT28) | AW28: 50 | BA28: {=INDEX(AM$6:AM$161,MATCH(0,COUNTIF($BA$5:BA27,AM$6:AM$161),0))} -> 27 | BD28: {=INDEX(AM$205:AM$236,MATCH(0,COUNTIF($BD$5:BD27,AM$205:AM$236),0))} -> #N/A
C29: Victron MultiPlus 12/1600/70-16 230V VE.Bus | D29: 488.51 | E29: 460.112 | F29: =$D29/1.219 -> 400.74651 | G29: =IFERROR(ROUNDUP(F29*'Customer Base'!$J$5,2),0) -> 6692.47 | H29: =$E29/1.219 -> 377.45037 | I29: =IFERROR(ROUNDUP(H29*'Customer Base'!$J$5,2),0) -> 6303.43 | J29: =ROUNDUP((M29/$L$4)*$L$3*3,-1) -> 3590 | K29: Dambai | L29: =J29/'Customer Base'!$J$5 -> 214.97006 | M29: 341 | N29: 24 | O29: =IF('Customer Base'!$I$15="MANUAL",IF(B29<>"",C29,""),IF('Customer Base'!$I$15="AUTOMATE",IF(A29<>"",C29,""),"")) | P29: ="Backup System with "&'Customer Base'!$J$7&"kVA inverter, "&'Customer Base'!$J$8&"kWh Battery, "&"and Remote Monitoring" -> Backup System with 5kVA inverter, 10kWh Battery, and Remote Monitoring | AM29: 1.6 | AN29: 12/1600 | AO29: =IF('Customer Base'!$I$15="MANUAL",IFERROR(AM29*B29,""),IF('Customer Base'!$I$15="AUTOMATE",IFERROR(AM29*A29,""),"")) -> 0 | AQ29: 12 | AR29: Multiplus | AS29: 1 | AT29: =IF(AND(AR29=$AY$1,$AZ$1=AN29),BA$1,"") | AV29: =IF(AU29<>"",AU29,AT29) | AW29: 70 | BA29: {=INDEX(AM$6:AM$161,MATCH(0,COUNTIF($BA$5:BA28,AM$6:AM$161),0))} -> 33.3 | BD29: {=INDEX(AM$205:AM$236,MATCH(0,COUNTIF($BD$5:BD28,AM$205:AM$236),0))} -> #N/A
C30: Victron MultiPlus 12/2000/80-32 230V VE.Bus | D30: 544.51 | E30: 512.86 | F30: =$D30/1.219 -> 446.68581 | G30: =IFERROR(ROUNDUP(F30*'Customer Base'!$J$5,2),0) -> 7459.66 | H30: =$E30/1.219 -> 420.7219 | I30: =IFERROR(ROUNDUP(H30*'Customer Base'!$J$5,2),0) -> 7026.06 | J30: =ROUNDUP((M30/$L$4)*$L$3*3,-1) -> 4180 | K30: Bono East Region | L30: =J30/'Customer Base'!$J$5 -> 250.2994 | M30: 398 | N30: 25 | O30: =IF('Customer Base'!$I$15="MANUAL",IF(B30<>"",C30,""),IF('Customer Base'!$I$15="AUTOMATE",IF(A30<>"",C30,""),"")) | P30: ="Grid-Tied Solar System with "&'Customer Base'!$J$7&"kVA inverter, "&'Customer Base'!$J$9&"kWp Solar Panels and Remote Monitoring" -> Grid-Tied Solar System with 5kVA inverter, 5.085kWp Solar Panels and Remote Monitoring | AM30: 2 | AN30: 12/2000 | AO30: =IF('Customer Base'!$I$15="MANUAL",IFERROR(AM30*B30,""),IF('Customer Base'!$I$15="AUTOMATE",IFERROR(AM30*A30,""),"")) -> 0 | AQ30: 12 | AR30: Multiplus | AS30: 1 | AT30: =IF(AND(AR30=$AY$1,$AZ$1=AN30),BA$1,"") | AV30: =IF(AU30<>"",AU30,AT30) | AW30: 80 | BA30: {=INDEX(AM$6:AM$161,MATCH(0,COUNTIF($BA$5:BA29,AM$6:AM$161),0))} -> 100 | BD30: {=INDEX(AM$205:AM$236,MATCH(0,COUNTIF($BD$5:BD29,AM$205:AM$236),0))} -> #N/A
A31: =IF(AND('Customer Base'!D$8=24,'Customer Base'!D$13="Victron",'Customer Base'!E$13="Multiplus",'Customer Base'!D$14>0,'Customer Base'!D$14<=0.5),'Customer Base'!D$15,IF(AND('Customer Base'!D$7="Mini-Grid",'Customer Base'!D$8=24,'Customer Base'!F$13="Victron",'Customer Base'!F$14>0,'Customer Base'!F$14<=0.5),'Customer Base'!F$15,"")) | C31: Victron MultiPlus 24/500/20-16 230V VE.Bus | D31: 261 | E31: 246.645 | F31: =$D31/1.219 -> 214.10993 | G31: =IFERROR(ROUNDUP(F31*'Customer Base'!$J$5,2),0) -> 3575.64 | H31: =$E31/1.219 -> 202.33388 | I31: =IFERROR(ROUNDUP(H31*'Customer Base'!$J$5,2),0) -> 3378.98 | J31: =ROUNDUP((M31/$L$4)*$L$3*3,-1) -> 4180 | K31: Techiman | L31: =J31/'Customer Base'!$J$5 -> 250.2994 | M31: 398 | N31: 26 | O31: =IF('Customer Base'!$I$15="MANUAL",IF(B31<>"",C31,""),IF('Customer Base'!$I$15="AUTOMATE",IF(A31<>"",C31,""),"")) | P31: ="Hybrid Solar System with "&'Customer Base'!$J$7&"kVA inverter, "&'Customer Base'!$J$8&"kWh Battery, "&'Customer Base'!$J$9&"kWp Solar Panels and Remote Monitoring" -> Hybrid Solar System with 5kVA inverter, 10kWh Battery, 5.085kWp Solar Panels and Remote Monitoring | AM31: 0.5 | AN31: 24/500 | AO31: =IF('Customer Base'!$I$15="MANUAL",IFERROR(AM31*B31,""),IF('Customer Base'!$I$15="AUTOMATE",IFERROR(AM31*A31,""),"")) | AQ31: 24 | AR31: Multiplus | AS31: 1 | AT31: =IF(AND(AR31=$AY$1,$AZ$1=AN31),BA$1,"") | AV31: =IF(AU31<>"",AU31,AT31) | AW31: 20 | BA31: {=INDEX(AM$6:AM$161,MATCH(0,COUNTIF($BA$5:BA30,AM$6:AM$161),0))} -> 4 | BD31: {=INDEX(AM$205:AM$236,MATCH(0,COUNTIF($BD$5:BD30,AM$205:AM$236),0))} -> #N/A
A32: =IF(AND('Customer Base'!D$8=24,'Customer Base'!D$13="Victron",'Customer Base'!E$13="Multiplus",'Customer Base'!D$14>0.5,'Customer Base'!D$14<=0.8),'Customer Base'!D$15,IF(AND('Customer Base'!D$7="Mini-Grid",'Customer Base'!D$8=24,'Customer Base'!F$13="Victron",'Customer Base'!F$14>0.5,'Customer Base'!F$14<=0.8),'Customer Base'!F$15,"")) | C32: Victron MultiPlus 24/800/35-16 230V VE.Bus | D32: 307.91 | E32: 290.012 | F32: =$D32/1.219 -> 252.59229 | G32: =IFERROR(ROUNDUP(F32*'Customer Base'!$J$5,2),0) -> 4218.3 | H32: =$E32/1.219 -> 237.90976 | I32: =IFERROR(ROUNDUP(H32*'Customer Base'!$J$5,2),0) -> 3973.1 | J32: =ROUNDUP((M32/$L$4)*$L$3*3,-1) -> 6790 | K32: North East Region | L32: =J32/'Customer Base'!$J$5 -> 406.58683 | M32: 646 | N32: 27 | O32: =IF('Customer Base'!$I$15="MANUAL",IF(B32<>"",C32,""),IF('Customer Base'!$I$15="AUTOMATE",IF(A32<>"",C32,""),"")) | P32: ="Hybrid Solar System with "&'Customer Base'!$J$7&"kVA inverter, "&'Customer Base'!$J$8&"kWh Battery, and "&'Customer Base'!$J$9&"kWp Solar Panels" -> Hybrid Solar System with 5kVA inverter, 10kWh Battery, and 5.085kWp Solar Panels | AM32: 0.8 | AN32: 24/800 | AO32: =IF('Customer Base'!$I$15="MANUAL",IFERROR(AM32*B32,""),IF('Customer Base'!$I$15="AUTOMATE",IFERROR(AM32*A32,""),"")) | AQ32: 24 | AR32: Multiplus | AS32: 1 | AT32: =IF(AND(AR32=$AY$1,$AZ$1=AN32),BA$1,"") | AV32: =IF(AU32<>"",AU32,AT32) | AW32: 35 | BA32: {=INDEX(AM$6:AM$161,MATCH(0,COUNTIF($BA$5:BA31,AM$6:AM$161),0))} -> #N/A | BD32: {=INDEX(AM$205:AM$236,MATCH(0,COUNTIF($BD$5:BD31,AM$205:AM$236),0))} -> #N/A
A33: =IF(AND('Customer Base'!D$8=24,'Customer Base'!D$13="Victron",'Customer Base'!E$13="Multiplus",'Customer Base'!D$14>0.8,'Customer Base'!D$14<=1.2),'Customer Base'!D$15,IF(AND('Customer Base'!D$7="Mini-Grid",'Customer Base'!D$8=24,'Customer Base'!F$13="Victron",'Customer Base'!F$14>0.8,'Customer Base'!F$14<=1.2),'Customer Base'!F$15,"")) | C33: Victron MultiPlus 24/1200/50-16 230V VE.Bus | D33: 429.83 | E33: 404.838 | F33: =$D33/1.219 -> 352.6087 | G33: =IFERROR(ROUNDUP(F33*'Customer Base'!$J$5,2),0) -> 5888.57 | H33: =$E33/1.219 -> 332.10664 | I33: =IFERROR(ROUNDUP(H33*'Customer Base'!$J$5,2),0) -> 5546.19 | J33: =ROUNDUP((M33/$L$4)*$L$3*3,-1) -> 6790 | K33: Nalerigu | L33: =J33/'Customer Base'!$J$5 -> 406.58683 | M33: 646 | N33: 28 | O33: =IF('Customer Base'!$I$15="MANUAL",IF(B33<>"",C33,""),IF('Customer Base'!$I$15="AUTOMATE",IF(A33<>"",C33,""),"")) | P33: ="Mini-grid Solar System with "&'Customer Base'!$J$7&"kVA inverter, "&'Customer Base'!$J$8&"kWh Battery, "&'Customer Base'!$J$9&"kWp Solar Panels and Remote Monitoring" -> Mini-grid Solar System with 5kVA inverter, 10kWh Battery, 5.085kWp Solar Panels and Remote Monitoring | AM33: 1.2 | AN33: 24/1200 | AO33: =IF('Customer Base'!$I$15="MANUAL",IFERROR(AM33*B33,""),IF('Customer Base'!$I$15="AUTOMATE",IFERROR(AM33*A33,""),"")) | AQ33: 24 | AR33: Multiplus | AS33: 1 | AT33: =IF(AND(AR33=$AY$1,$AZ$1=AN33),BA$1,"") | AV33: =IF(AU33<>"",AU33,AT33) | AW33: 50 | BD33: {=INDEX(AM$205:AM$236,MATCH(0,COUNTIF($BD$5:BD32,AM$205:AM$236),0))} -> #N/A
A34: =IF(AND('Customer Base'!D$8=24,'Customer Base'!D$13="Victron",'Customer Base'!E$13="Multiplus",'Customer Base'!D$14>1.2,'Customer Base'!D$14<=1.6),'Customer Base'!D$15,IF(AND('Customer Base'!D$7="Mini-Grid",'Customer Base'!D$8=24,'Customer Base'!F$13="Victron",'Customer Base'!F$14>1.2,'Customer Base'!F$14<=1.6),'Customer Base'!F$15,"")) | C34: Victron MultiPlus 24/1600/70-16 230V VE.Bus | D34: 488.51 | E34: 460.112 | F34: =$D34/1.219 -> 400.74651 | G34: =IFERROR(ROUNDUP(F34*'Customer Base'!$J$5,2),0) -> 6692.47 | H34: =$E34/1.219 -> 377.45037 | I34: =IFERROR(ROUNDUP(H34*'Customer Base'!$J$5,2),0) -> 6303.43 | J34: =ROUNDUP((M34/$L$4)*$L$3*3,-1) -> 8220 | K34: Savanna Region | L34: =J34/'Customer Base'!$J$5 -> 492.21557 | M34: 782 | N34: 29 | O34: =IF('Customer Base'!$I$15="MANUAL",IF(B34<>"",C34,""),IF('Customer Base'!$I$15="AUTOMATE",IF(A34<>"",C34,""),"")) | AM34: 1.6 | AN34: 24/1600 | AO34: =IF('Customer Base'!$I$15="MANUAL",IFERROR(AM34*B34,""),IF('Customer Base'!$I$15="AUTOMATE",IFERROR(AM34*A34,""),"")) | AQ34: 24 | AR34: Multiplus | AS34: 1 | AT34: =IF(AND(AR34=$AY$1,$AZ$1=AN34),BA$1,"") | AV34: =IF(AU34<>"",AU34,AT34) | AW34: 70 | BD34: {=INDEX(AM$205:AM$236,MATCH(0,COUNTIF($BD$5:BD33,AM$205:AM$236),0))} -> #N/A
A35: =IF(AND('Customer Base'!D$8=24,'Customer Base'!D$13="Victron",'Customer Base'!E$13="Multiplus",'Customer Base'!D$14>1.6,'Customer Base'!D$14<=2),'Customer Base'!D$15,IF(AND('Customer Base'!D$7="Mini-Grid",'Customer Base'!D$8=24,'Customer Base'!F$13="Victron",'Customer Base'!F$14>1.6,'Customer Base'!F$14<=2),'Customer Base'!F$15,"")) | C35: Victron MultiPlus 24/2000/80-32 230V VE.Bus | D35: 544.51 | E35: 512.86 | F35: =$D35/1.219 -> 446.68581 | G35: =IFERROR(ROUNDUP(F35*'Customer Base'!$J$5,2),0) -> 7459.66 | H35: =$E35/1.219 -> 420.7219 | I35: =IFERROR(ROUNDUP(H35*'Customer Base'!$J$5,2),0) -> 7026.06 | J35: =ROUNDUP((M35/$L$4)*$L$3*3,-1) -> 8220 | K35: Damango | L35: =J35/'Customer Base'!$J$5 -> 492.21557 | M35: 782 | N35: 30 | O35: =IF('Customer Base'!$I$15="MANUAL",IF(B35<>"",C35,""),IF('Customer Base'!$I$15="AUTOMATE",IF(A35<>"",C35,""),"")) | AM35: 2 | AN35: 24/2000 | AO35: =IF('Customer Base'!$I$15="MANUAL",IFERROR(AM35*B35,""),IF('Customer Base'!$I$15="AUTOMATE",IFERROR(AM35*A35,""),"")) | AQ35: 24 | AR35: Multiplus | AS35: 1 | AT35: =IF(AND(AR35=$AY$1,$AZ$1=AN35),BA$1,"") | AV35: =IF(AU35<>"",AU35,AT35) | AW35: 80 | BD35: {=INDEX(AM$205:AM$236,MATCH(0,COUNTIF($BD$5:BD34,AM$205:AM$236),0))} -> #N/A
C36: Victron MultiPlus 24/3000/35-50 230V VE.Bus | D36: 1293.1 | E36: 1217.916 | F36: =$D36/1.219 -> 1060.7875 | G36: =IFERROR(ROUNDUP(F36*'Customer Base'!$J$5,2),0) -> 17715.16 | H36: =$E36/1.219 -> 999.11075 | I36: =IFERROR(ROUNDUP(H36*'Customer Base'!$J$5,2),0) -> 16685.15 | J36: =ROUNDUP((M36/$L$4)*$L$3*3,-1) -> 6600 | K36: Northern Region | L36: =J36/'Customer Base'!$J$5 -> 395.20958 | M36: 628 | N36: 31 | O36: =IF('Customer Base'!$I$15="MANUAL",IF(B36<>"",C36,""),IF('Customer Base'!$I$15="AUTOMATE",IF(A36<>"",C36,""),"")) | AM36: 3 | AN36: 24/3000/70-50 | AO36: =IF('Customer Base'!$I$15="MANUAL",IFERROR(AM36*B36,""),IF('Customer Base'!$I$15="AUTOMATE",IFERROR(AM36*A36,""),"")) -> 0 | AQ36: 24 | AR36: Multiplus | AS36: 1 | AT36: =IF(AND(AR36=$AY$1,$AZ$1=AN36),BA$1,"") | AV36: =IF(AU36<>"",AU36,AT36) | AW36: 70
A37: =IF(AND('Customer Base'!D$8=48,'Customer Base'!D$13="Victron",'Customer Base'!E$13="Multiplus",'Customer Base'!D$14>0,'Customer Base'!D$14<=0.5),'Customer Base'!D$15,IF(AND('Customer Base'!D$7="Mini-Grid",'Customer Base'!D$8=48,'Customer Base'!F$13="Victron",'Customer Base'!F$14>0,'Customer Base'!F$14<=0.5),'Customer Base'!F$15,"")) | C37: Victron MultiPlus 48/500/6-16 230V VE.Bus | D37: 261 | E37: 246.645 | F37: =$D37/1.219 -> 214.10993 | G37: =IFERROR(ROUNDUP(F37*'Customer Base'!$J$5,2),0) -> 3575.64 | H37: =$E37/1.219 -> 202.33388 | I37: =IFERROR(ROUNDUP(H37*'Customer Base'!$J$5,2),0) -> 3378.98 | J37: =ROUNDUP((M37/$L$4)*$L$3*3,-1) -> 6600 | K37: Tamale | L37: =J37/'Customer Base'!$J$5 -> 395.20958 | M37: 628 | N37: 32 | O37: =IF('Customer Base'!$I$15="MANUAL",IF(B37<>"",C37,""),IF('Customer Base'!$I$15="AUTOMATE",IF(A37<>"",C37,""),"")) | AM37: 0.5 | AN37: 48/500 | AO37: =IF('Customer Base'!$I$15="MANUAL",IFERROR(AM37*B37,""),IF('Customer Base'!$I$15="AUTOMATE",IFERROR(AM37*A37,""),"")) | AQ37: 48 | AR37: Multiplus | AS37: 1 | AT37: =IF(AND(AR37=$AY$1,$AZ$1=AN37),BA$1,"") | AV37: =IF(AU37<>"",AU37,AT37) | AW37: 6
A38: =IF(AND('Customer Base'!D$8=48,'Customer Base'!D$13="Victron",'Customer Base'!E$13="Multiplus",'Customer Base'!D$14>0.5,'Customer Base'!D$14<=0.8),'Customer Base'!D$15,IF(AND('Customer Base'!D$7="Mini-Grid",'Customer Base'!D$8=48,'Customer Base'!F$13="Victron",'Customer Base'!F$14>0.5,'Customer Base'!F$14<=0.8),'Customer Base'!F$15,"")) | C38: Victron MultiPlus 48/800/9-16 230V VE.Bus | D38: 307.91 | E38: 290.012 | F38: =$D38/1.219 -> 252.59229 | G38: =IFERROR(ROUNDUP(F38*'Customer Base'!$J$5,2),0) -> 4218.3 | H38: =$E38/1.219 -> 237.90976 | I38: =IFERROR(ROUNDUP(H38*'Customer Base'!$J$5,2),0) -> 3973.1 | L38: =IF(H38>F38,"lkkajdfkj","") | N38: 33 | O38: =IF('Customer Base'!$I$15="MANUAL",IF(B38<>"",C38,""),IF('Customer Base'!$I$15="AUTOMATE",IF(A38<>"",C38,""),"")) | AM38: 0.8 | AN38: 48/800 | AO38: =IF('Customer Base'!$I$15="MANUAL",IFERROR(AM38*B38,""),IF('Customer Base'!$I$15="AUTOMATE",IFERROR(AM38*A38,""),"")) | AQ38: 48 | AR38: Multiplus | AS38: 1 | AT38: =IF(AND(AR38=$AY$1,$AZ$1=AN38),BA$1,"") | AV38: =IF(AU38<>"",AU38,AT38) | AW38: 9
A39: =IF(AND('Customer Base'!D$8=48,'Customer Base'!D$13="Victron",'Customer Base'!E$13="Multiplus",'Customer Base'!D$14>0.8,'Customer Base'!D$14<=1.2),'Customer Base'!D$15,IF(AND('Customer Base'!D$7="Mini-Grid",'Customer Base'!D$8=48,'Customer Base'!F$13="Victron",'Customer Base'!F$14>0.8,'Customer Base'!F$14<=1.2),'Customer Base'!F$15,"")) | C39: Victron MultiPlus 48/1200/13-16 230V VE.Bus | D39: 429.83 | E39: 404.838 | F39: =$D39/1.219 -> 352.6087 | G39: =IFERROR(ROUNDUP(F39*'Customer Base'!$J$5,2),0) -> 5888.57 | H39: =$E39/1.219 -> 332.10664 | I39: =IFERROR(ROUNDUP(H39*'Customer Base'!$J$5,2),0) -> 5546.19 | L39: =IF(H39>F39,"lkkajdfkj","") | N39: 34 | O39: =IF('Customer Base'!$I$15="MANUAL",IF(B39<>"",C39,""),IF('Customer Base'!$I$15="AUTOMATE",IF(A39<>"",C39,""),"")) | AM39: 1.2 | AN39: 48/1200 | AO39: =IF('Customer Base'!$I$15="MANUAL",IFERROR(AM39*B39,""),IF('Customer Base'!$I$15="AUTOMATE",IFERROR(AM39*A39,""),"")) | AQ39: 48 | AR39: Multiplus | AS39: 1 | AT39: =IF(AND(AR39=$AY$1,$AZ$1=AN39),BA$1,"") | AV39: =IF(AU39<>"",AU39,AT39) | AW39: 13
A40: =IF(AND('Customer Base'!D$8=48,'Customer Base'!D$13="Victron",'Customer Base'!E$13="Multiplus",'Customer Base'!D$14>1.2,'Customer Base'!D$14<=1.6),'Customer Base'!D$15,IF(AND('Customer Base'!D$7="Mini-Grid",'Customer Base'!D$8=48,'Customer Base'!F$13="Victron",'Customer Base'!F$14>1.2,'Customer Base'!F$14<=1.6),'Customer Base'!F$15,"")) | C40: Victron MultiPlus 48/1600/20-16 230V VE.Bus | D40: 488.51 | E40: 460.112 | F40: =$D40/1.219 -> 400.74651 | G40: =IFERROR(ROUNDUP(F40*'Customer Base'!$J$5,2),0) -> 6692.47 | H40: =$E40/1.219 -> 377.45037 | I40: =IFERROR(ROUNDUP(H40*'Customer Base'!$J$5,2),0) -> 6303.43 | L40: =IF(H40>F40,"lkkajdfkj","") | N40: 35 | O40: =IF('Customer Base'!$I$15="MANUAL",IF(B40<>"",C40,""),IF('Customer Base'!$I$15="AUTOMATE",IF(A40<>"",C40,""),"")) | AM40: 1.6 | AN40: 48/1600 | AO40: =IF('Customer Base'!$I$15="MANUAL",IFERROR(AM40*B40,""),IF('Customer Base'!$I$15="AUTOMATE",IFERROR(AM40*A40,""),"")) | AQ40: 48 | AR40: Multiplus | AS40: 1 | AT40: =IF(AND(AR40=$AY$1,$AZ$1=AN40),BA$1,"") | AV40: =IF(AU40<>"",AU40,AT40) | AW40: 20
...

Sheet Client List
B1: CLIENT NAME | C1: TOWN | D1: CITY/REGION | E1: PHONE NUMBER | F1: CODE | G1: CONTACT PEERSON | H1: EMAIL ADDRESS | N1: =SUM(Items!A242:A254) -> 9 | O1: =IF(MOD($N$1,ROW())=0,ROW(),"") -> 1 | P1: =IFERROR(LARGE(O$1:O$100, ROW()), "") -> 9 | Q1: =_xlfn.TEXTJOIN(", ", TRUE, P1:P100) -> 9, 3, 1
B2: Tilman Rippel | C2: Mankoadze - Winneba | D2: Central Region | E2: 0545245745 | F2: =UPPER(LEFT(B2,1)) & IFERROR(UPPER(LEFT(MID(B2,FIND(" ",B2)+1,LEN(B2)),1)),"") & IFERROR(UPPER(LEFT(MID(B2,FIND(" ",B2,FIND(" ",B2)+1)+1,LEN(B2)),1)),"") & IFERROR(UPPER(LEFT(MID(B2,FIND(" ",B2,FIND(" ",B2,FIND(" ",B2)+1)+1)+1,LEN(B2)),1)),"") -> TR | I2: Username | J2: Passcode | O2: =IF(MOD($N$1,ROW())=0,ROW(),"") | P2: =IFERROR(LARGE(O$1:O$100, ROW()), "") -> 3 | U2: =IF(MOD($T$500,ROW())=0,ROW(),"") -> 2
B3: Apostle Baidoo | C3: Kasoa | D3: Accra | E3: 0504253726 | F3: =UPPER(LEFT(B3,1)) & IFERROR(UPPER(LEFT(MID(B3,FIND(" ",B3)+1,LEN(B3)),1)),"") & IFERROR(UPPER(LEFT(MID(B3,FIND(" ",B3,FIND(" ",B3)+1)+1,LEN(B3)),1)),"") & IFERROR(UPPER(LEFT(MID(B3,FIND(" ",B3,FIND(" ",B3,FIND(" ",B3)+1)+1)+1,LEN(B3)),1)),"") -> AB | I3: Emmanuel | J3: 1234 | O3: =IF(MOD($N$1,ROW())=0,ROW(),"") -> 3 | P3: =IFERROR(LARGE(O$1:O$100, ROW()), "") -> 1 | U3: =IF(MOD($T$500,ROW())=0,ROW(),"") -> 3
